2021-08-28 22:27:01,023 CRITICAL This is a critical level msg!: 
Traceback (most recent call last):
  File "/tmp/ipykernel_12890/4196050988.py", line 2, in <module>
    df = pd.read_csv('../daa/data.csv')
  File "/root/anaconda3/envs/tensorflow/lib/python3.7/site-packages/pandas/util/_decorators.py", line 311, in wrapper
    return func(*args, **kwargs)
  File "/root/anaconda3/envs/tensorflow/lib/python3.7/site-packages/pandas/io/parsers/readers.py", line 586, in read_csv
    return _read(filepath_or_buffer, kwds)
  File "/root/anaconda3/envs/tensorflow/lib/python3.7/site-packages/pandas/io/parsers/readers.py", line 482, in _read
    parser = TextFileReader(filepath_or_buffer, **kwds)
  File "/root/anaconda3/envs/tensorflow/lib/python3.7/site-packages/pandas/io/parsers/readers.py", line 811, in __init__
    self._engine = self._make_engine(self.engine)
  File "/root/anaconda3/envs/tensorflow/lib/python3.7/site-packages/pandas/io/parsers/readers.py", line 1040, in _make_engine
    return mapping[engine](self.f, **self.options)  # type: ignore[call-arg]
  File "/root/anaconda3/envs/tensorflow/lib/python3.7/site-packages/pandas/io/parsers/c_parser_wrapper.py", line 51, in __init__
    self._open_handles(src, kwds)
  File "/root/anaconda3/envs/tensorflow/lib/python3.7/site-packages/pandas/io/parsers/base_parser.py", line 229, in _open_handles
    errors=kwds.get("encoding_errors", "strict"),
  File "/root/anaconda3/envs/tensorflow/lib/python3.7/site-packages/pandas/io/common.py", line 706, in get_handle
    newline="",
FileNotFoundError: [Errno 2] No such file or directory: '../daa/data.csv'
